/**
 * Tests for Next.js Sentry error boundary components
 *
 * @deprecated These tests are skipped pending Sentry v9 migration
 */

// @ts-nocheck - Skip type checking for v8 â†’ v9 migration

import '@testing-library/jest-dom';
import { fireEvent, render, screen } from '@testing-library/react';
import { beforeEach, describe, expect, vi } from 'vitest';
import { ErrorBoundary } from '../../src/plugins/sentry-nextjs/components/ErrorBoundary';
import ErrorPage, { SimpleErrorPage } from '../../src/plugins/sentry-nextjs/components/ErrorPage';
import GlobalError from '../../src/plugins/sentry-nextjs/components/GlobalError';

// Mock Sentry first
vi.mock('@sentry/nextjs', () => ({
  captureException: vi.fn(),
}));

describe.todo('sentry Next.js Error Components', () => {
  beforeEach(() => {
    vi.clearAllMocks();
  });

  describe.todo('errorPage Component', () => {
    const mockError = new Error('Test error');
    const mockReset = vi.fn();

    beforeEach(() => {
      mockReset.mockClear();
    });

    test('should render error page with all elements', () => {
      render(<ErrorPage error={mockError} reset={mockReset} />);

      expect(screen.getByText('Oops!')).toBeInTheDocument();
      expect(screen.getByText('Something went wrong')).toBeInTheDocument();
      expect(screen.getByText(/We've been notified about this error/)).toBeInTheDocument();
      expect(screen.getByText('Try again')).toBeInTheDocument();
      expect(screen.getByText('Go home')).toBeInTheDocument();
    });

    test('should capture exception on mount', () => {
      render(<ErrorPage error={mockError} reset={mockReset} />);

      expect(mockCaptureException).toHaveBeenCalledWith(mockError, {
        tags: {
          component: 'ErrorPage',
          errorType: 'page',
        },
        contexts: {
          error: {
            digest: undefined,
          },
        },
      });
    });

    test('should capture exception with digest when provided', () => {
      const errorWithDigest = { ...mockError, digest: 'abc123' } as Error & { digest?: string };
      render(<ErrorPage error={errorWithDigest} reset={mockReset} />);

      expect(mockCaptureException).toHaveBeenCalledWith(errorWithDigest, {
        tags: {
          component: 'ErrorPage',
          errorType: 'page',
        },
        contexts: {
          error: {
            digest: 'abc123',
          },
        },
      });
    });

    test('should display error digest when provided', () => {
      const errorWithDigest = { ...mockError, digest: 'abc123' } as Error & { digest?: string };
      render(<ErrorPage error={errorWithDigest} reset={mockReset} />);

      expect(screen.getByText('Error ID: abc123')).toBeInTheDocument();
    });

    test('should not display error digest when not provided', () => {
      render(<ErrorPage error={mockError} reset={mockReset} />);

      expect(screen.queryByText(/Error ID:/)).not.toBeInTheDocument();
    });

    test('should call reset function when Try again button is clicked', () => {
      render(<ErrorPage error={mockError} reset={mockReset} />);

      const tryAgainButton = screen.getByText('Try again');
      fireEvent.click(tryAgainButton);

      expect(mockReset).toHaveBeenCalledTimes(1);
    });

    test('should navigate to home when Go home button is clicked', () => {
      // Mock window.location
      const originalLocation = window.location;
      delete (window as any).location;
      window.location = { ...originalLocation, href: '' };

      render(<ErrorPage error={mockError} reset={mockReset} />);

      const goHomeButton = screen.getByText('Go home');
      fireEvent.click(goHomeButton);

      expect(window.location.href).toBe('/');

      // Restore
      window.location = originalLocation;
    });
  });

  describe.todo('simpleErrorPage Component', () => {
    const mockError = new Error('Test error');
    const mockReset = vi.fn();

    test('should render simple error page', () => {
      render(<SimpleErrorPage error={mockError} reset={mockReset} />);

      expect(screen.getByText('Something went wrong!')).toBeInTheDocument();
      expect(screen.getByText('Try again')).toBeInTheDocument();
    });

    test('should capture exception on mount', () => {
      render(<SimpleErrorPage error={mockError} reset={mockReset} />);

      expect(mockCaptureException).toHaveBeenCalledWith(mockError);
    });

    test('should call reset function when button is clicked', () => {
      render(<SimpleErrorPage error={mockError} reset={mockReset} />);

      const tryAgainButton = screen.getByText('Try again');
      fireEvent.click(tryAgainButton);

      expect(mockReset).toHaveBeenCalledTimes(1);
    });
  });

  describe.todo('errorBoundary Component', () => {
    const ThrowError = ({ shouldThrow }: { shouldThrow: boolean }) => {
      if (shouldThrow) {
        throw new Error('Test boundary error');
      }
      return <div>No error</div>;
    };

    test('should render children when no error occurs', () => {
      render(
        <ErrorBoundary>
          <ThrowError shouldThrow={false} />
        </ErrorBoundary>,
      );

      expect(screen.getByText('No error')).toBeInTheDocument();
    });

    test('should render error UI when error occurs', () => {
      // Suppress console.error for this test
      const consoleSpy = vi.spyOn(console, 'error').mockImplementation(() => {});

      render(
        <ErrorBoundary>
          <ThrowError shouldThrow={true} />
        </ErrorBoundary>,
      );

      expect(screen.getByText('Oops!')).toBeInTheDocument();
      expect(screen.getByText('Something went wrong')).toBeInTheDocument();

      consoleSpy.mockRestore();
    });

    test('should capture exception when error boundary catches error', () => {
      const consoleSpy = vi.spyOn(console, 'error').mockImplementation(() => {});

      render(
        <ErrorBoundary>
          <ThrowError shouldThrow={true} />
        </ErrorBoundary>,
      );

      expect(mockCaptureException).toHaveBeenCalledWith(
        expect.objectContaining({
          message: 'Test boundary error',
        }),
        expect.objectContaining({
          tags: {
            component: 'ErrorBoundary',
            errorType: 'boundary',
          },
        }),
      );

      consoleSpy.mockRestore();
    });

    test('should render custom fallback when provided', () => {
      const consoleSpy = vi.spyOn(console, 'error').mockImplementation(() => {});
      const CustomFallback = ({ error, reset }: { error: Error; reset: () => void }) => (
        <div>
          Custom error: {error.message}
          <button onClick={reset}>Custom reset</button>
        </div>
      );

      render(
        <ErrorBoundary fallback={CustomFallback}>
          <ThrowError shouldThrow={true} />
        </ErrorBoundary>,
      );

      expect(screen.getByText('Custom error: Test boundary error')).toBeInTheDocument();
      expect(screen.getByText('Custom reset')).toBeInTheDocument();

      consoleSpy.mockRestore();
    });

    test('should reset error state when reset is called', () => {
      const consoleSpy = vi.spyOn(console, 'error').mockImplementation(() => {});

      const { rerender } = render(
        <ErrorBoundary>
          <ThrowError shouldThrow={true} />
        </ErrorBoundary>,
      );

      // Error should be shown
      expect(screen.getByText('Try again')).toBeInTheDocument();

      // Click reset
      fireEvent.click(screen.getByText('Try again'));

      // Rerender with no error
      rerender(
        <ErrorBoundary>
          <ThrowError shouldThrow={false} />
        </ErrorBoundary>,
      );

      expect(screen.getByText('No error')).toBeInTheDocument();

      consoleSpy.mockRestore();
    });
  });

  describe.todo('globalError Component', () => {
    const mockError = new Error('Global error');

    test('should render global error page', () => {
      render(<GlobalError error={mockError} />);

      // Check for HTML structure
      const htmlElement = document.querySelector('html');
      const bodyElement = document.querySelector('body');

      expect(htmlElement).toBeInTheDocument();
      expect(bodyElement).toBeInTheDocument();
    });

    test('should capture exception on mount', () => {
      render(<GlobalError error={mockError} />);

      expect(mockCaptureException).toHaveBeenCalledWith(mockError);
    });

    test('should render NextError component inside', () => {
      render(<GlobalError error={mockError} />);

      // The NextError component should be rendered
      // This is a basic check since we can't easily test the NextError component itself
      expect(document.querySelector('body')).toBeInTheDocument();
    });

    test('should capture exception with digest when provided', () => {
      const errorWithDigest = { ...mockError, digest: 'xyz789' } as Error & { digest?: string };
      render(<GlobalError error={errorWithDigest} />);

      expect(mockCaptureException).toHaveBeenCalledWith(errorWithDigest);
    });
  });

  describe.todo('component Error Handling', () => {
    test('should handle error objects without digest property', () => {
      const basicError = new Error('Basic error');
      render(<ErrorPage error={basicError} reset={vi.fn()} />);

      expect(mockCaptureException).toHaveBeenCalledWith(basicError, {
        tags: {
          component: 'ErrorPage',
          errorType: 'page',
        },
        contexts: {
          error: {
            digest: undefined,
          },
        },
      });
    });

    test('should handle undefined error gracefully', () => {
      const consoleSpy = vi.spyOn(console, 'error').mockImplementation(() => {});

      // This should not crash
      render(<ErrorPage error={undefined as any} reset={vi.fn()} />);

      expect(screen.getByText('Something went wrong')).toBeInTheDocument();

      consoleSpy.mockRestore();
    });

    test('should handle null reset function gracefully', () => {
      const mockError = new Error('Test error');

      // This should not crash
      render(<ErrorPage error={mockError} reset={null as any} />);

      expect(screen.getByText('Try again')).toBeInTheDocument();
    });
  });
});
